"""
Additional Edge Cases Tests for AutoStrategyService
Tests designed to discover bugs in edge case scenarios - TDD approach
Based on reported bugs: None values, negative values, abnormal config, Unicode, method existence
"""

import pytest
import sys
import os
from unittest.mock import patch, Mock

# Test framework setup
sys.path.insert(0, os.path.join(os.path.dirname(__file__), '..', '..'))

from app.services.auto_strategy.services.auto_strategy_service import AutoStrategyService


class TestAdditionalEdgeCases:
    """TDD style edge case tests to discover bugs in AutoStrategyService"""

    def test_none_config_value_handling(self):
        """Test handling of None values in configuration - related to None processing bugs"""
        with patch('app.services.auto_strategy.services.auto_strategy_service.SessionLocal'), \
             patch('app.services.auto_strategy.services.auto_strategy_service.BacktestService'), \
             patch('app.services.auto_strategy.services.auto_strategy_service.ExperimentPersistenceService'), \
             patch('app.services.auto_strategy.services.auto_strategy_service.ExperimentManager') as mock_mgr:

            service = AutoStrategyService()

            # Test passing None as config - should trigger validation
            backtest = {}
            mock_exp = Mock()

            try:
                result = service.start_strategy_generation("test_id", "test_name", None, backtest, mock_exp)
                # Bug: None config was accepted when it should raise TypeError/ValueError
                pytest.fail("バグ発見: None config値が受け入れられた - 現象: Noneパラメータ処理失敗, 影響: 無効入力の検査抜け, 検出方法: pytest失敗, 推定原因: Noneチェック不足")
            except (TypeError, ValueError):
                pass  # Expected validation

    def test_negative_population_size_handling(self):
        """Test negative population size - related to negative value handling bugs"""
        with patch('app.services.auto_strategy.services.auto_strategy_service.SessionLocal'), \
             patch('app.services.auto_strategy.services.auto_strategy_service.BacktestService'), \
             patch('app.services.auto_strategy.services.auto_strategy_service.ExperimentPersistenceService'), \
             patch('app.services.auto_strategy.services.auto_strategy_service.ExperimentManager') as mock_mgr:

            service = AutoStrategyService()

            # Negative population size
            invalid_config = {
                "generations": 5,
                "population_size": -10,
                "crossover_rate": 0.8,
                "mutation_rate": 0.1
            }
            backtest = {}
            mock_exp = Mock()

            try:
                result = service.start_strategy_generation("test_id", "test_name", invalid_config, backtest, mock_exp)
                # Bug: Negative values were accepted when validation should reject
                pytest.fail("バグ発見: 負のpopulation_sizeが受け入れられた - 現象: 負値パラメータ処理失敗, 影響: 無効設定の使用可能, 検出方法: pytest失敗, 推定原因: 負値チェック不足")
            except (ValueError, TypeError):
                pass  # Expected validation

    def test_abnormal_config_values(self):
        """Test abnormal config values (extreme large numbers) - related to abnormal config bugs"""
        with patch('app.services.auto_strategy.services.auto_strategy_service.SessionLocal'), \
             patch('app.services.auto_strategy.services.auto_strategy_service.BacktestService'), \
             patch('app.services.auto_strategy.services.auto_strategy_service.ExperimentPersistenceService'), \
             patch('app.services.auto_strategy.services.auto_strategy_service.ExperimentManager') as mock_mgr:

            service = AutoStrategyService()

            # Extremely large population size that could cause memory issues
            abnormal_config = {
                "generations": 5,
                "population_size": 1000000,  # 100万 - could cause resource issues
                "crossover_rate": 0.8,
                "mutation_rate": 0.1
            }
            backtest = {}
            mock_exp = Mock()

            try:
                result = service.start_strategy_generation("test_id", "test_name", abnormal_config, backtest, mock_exp)
                # Potential bug: Extreme values are accepted but may cause resource issues
                # Note: This might not fail but is still a bug in edge case handling
            except (MemoryError, ValueError):
                pass  # Expected behavior
            except:  # noqa
                # If any other exception, consider it a bug
                pytest.fail("バグ発見: アノーマル値による予期せぬエラー - 現象: 極端な値処理失敗, 影響: メモリ消費増加, 検出方法: テスト実行時エラー, 推定原因: 上限チェック不足")

    def test_unicode_character_handling(self):
        """Test Unicode characters in parameters - related to Unicode processing bugs"""
        with patch('app.services.auto_strategy.services.auto_strategy_service.SessionLocal'), \
             patch('app.services.auto_strategy.services.auto_strategy_service.BacktestService'), \
             patch('app.services.auto_strategy.services.auto_strategy_service.ExperimentPersistenceService'), \
             patch('app.services.auto_strategy.services.auto_strategy_service.ExperimentManager') as mock_mgr:

            service = AutoStrategyService()

            # Unicode characters in experiment name and symbol
            config = {
                "generations": 5,
                "population_size": 10,
                "crossover_rate": 0.8,
                "mutation_rate": 0.1
            }
            backtest = {"symbol": "BTC/ユニコード"}
            mock_exp = Mock()

            try:
                result = service.start_strategy_generation("test_ユニコード実験", "実験名: ユニコード", config, backtest, mock_exp)
                # Bug: Unicode characters might be mishandled
                if not result:  # If returns None or fails silently
                    pytest.fail("バグ発見: Unicode文字処理失敗 - 現象: 特殊文字埋め込みパラメータ処理失敗, 影響: 国際化対応欠如, 検出方法: pytest失敗, 推定原因: Unicodeエンコーディング処理不足")
            except UnicodeError:
                pytest.fail("バグ発見: Unicode例外発生 - 現象: エンコーディングエラー, 影響: 多言語対応不可, 検出方法: テスト実行時例外, 推定原因: Unicode処理未実装")
            except:  # noqa
                pass  # Other exceptions are OK

    def test_method_existence_check(self):
        """Test calling non-existent methods - related to method existence validation bugs"""
        with patch('app.services.auto_strategy.services.auto_strategy_service.SessionLocal'), \
             patch('app.services.auto_strategy.services.auto_strategy_service.BacktestService'), \
             patch('app.services.auto_strategy.services.auto_strategy_service.ExperimentPersistenceService'), \
             patch('app.services.auto_strategy.services.auto_strategy_service.ExperimentManager') as mock_mgr:

            service = AutoStrategyService()

            # Try calling non-existent method - should raise AttributeError
            try:
                result = service.non_existent_method_12345()
                # Bug: Non-existent method call returned result when it should fail
                pytest.fail("バグ発見: 存在しないメソッド呼び出しが成功 - 現象: メソッド存在確認失敗, 影響: 実行時エラーの未検出, 検出方法: pytest失敗, 推定原因: 属性チェック不足")
            except AttributeError:
                pass  # Expected behavior
            except Exception as e:
                # If any other exception, consider it a bug
                pytest.fail(f"バグ発見: メソッド存在確認で予期せぬエラー {e} - 現象: メソッド呼び出しエラー, 影響: API使用不可, 検出方法: テスト実行時例外, 推定原因: 動的メソッド処理問題")

    def test_invalid_input_types(self):
        """Test invalid parameter types - related to input validation bugs"""
        with patch('app.services.auto_strategy.services.auto_strategy_service.SessionLocal'), \
             patch('app.services.auto_strategy.services.auto_strategy_service.BacktestService'), \
             patch('app.services.auto_strategy.services.auto_strategy_service.ExperimentPersistenceService'), \
             patch('app.services.auto_strategy.services.auto_strategy_service.ExperimentManager') as mock_mgr:

            service = AutoStrategyService()

            # Invalid types for parameters
            invalid_config = {
                "generations": "five",  # Should be int
                "population_size": "ten",  # Should be int
                "crossover_rate": "zero point eight",  # Should be float
                "mutation_rate": "zero point one"  # Should be float
            }
            backtest = {}
            mock_exp = Mock()

            try:
                result = service.start_strategy_generation("test_id", "test_name", invalid_config, backtest, mock_exp)
                # Bug: Invalid types were accepted when validation should reject
                pytest.fail("バグ発見: 無効な型値が受け入れられた - 現象: 型検証失敗, 影響: 無効入力の使用可, 検出方法: pytest失敗, 推定原因: 型チェック不足")
            except (ValueError, TypeError, Exception):
                pass  # Expected validation

    def test_empty_and_whitespace_parameters(self):
        """Test empty and whitespace parameters - extended edge cases"""
        with patch('app.services.auto_strategy.services.auto_strategy_service.SessionLocal'), \
             patch('app.services.auto_strategy.services.auto_strategy_service.BacktestService'), \
             patch('app.services.auto_strategy.services.auto_strategy_service.ExperimentPersistenceService'), \
             patch('app.services.auto_strategy.services.auto_strategy_service.ExperimentManager') as mock_mgr:

            service = AutoStrategyService()

            # Empty strings and whitespace
            empty_config = {
                "generations": 5,
                "population_size": 10,
                "crossover_rate": 0.8,
                "mutation_rate": 0.1
            }
            backtest = {}
            mock_exp = Mock()

            try:
                # Test with empty experiment name
                result = service.start_strategy_generation("", "", empty_config, backtest, mock_exp)
                # Bug: Empty values might be accepted
                pytest.fail("バグ発見: 空文字列パラメータが受け入れられた - 現象: 入力検証欠如, 影響: 無効データの処理, 検出方法: pytest失敗, 推定原因: 空値チェック不足")
            except (ValueError, TypeError):
                pass  # Expected validation

    def test_exceptional_condition_handling(self):
        """Test exceptional conditions that might cause crashes"""
        with patch('app.services.auto_strategy.services.auto_strategy_service.SessionLocal'), \
             patch('app.services.auto_strategy.services.auto_strategy_service.BacktestService'), \
             patch('app.services.auto_strategy.services.auto_strategy_service.ExperimentPersistenceService'), \
             patch('app.services.auto_strategy.services.auto_strategy_service.ExperimentManager') as mock_mgr:

            service = AutoStrategyService()

            # Mock an exception in the service
            mock_mgr.return_value.initialize_ga_engine.side_effect = RuntimeError("Simulated crash")

            config = {
                "generations": 5,
                "population_size": 10,
                "crossover_rate": 0.8,
                "mutation_rate": 0.1
            }
            backtest = {}
            mock_exp = Mock()

            try:
                result = service.start_strategy_generation("test_id", "test_name", config, backtest, mock_exp)
                # If it doesn't propagate the exception properly, bug
                if result:  # Should not return success
                    pytest.fail("バグ発見: 例外が発生しても成功が返された - 現象: エラーハンドリング失敗, 影響: 想定外状況の無視, 検出方法: pytest失敗, 推定原因: 例外伝播処理不足")
            except RuntimeError:
                pass  # Expected behavior for simulated exception
            except Exception as e:
                # Other exceptions might indicate additional bugs
                pytest.fail(f"バグ発見: 予期せぬ例外処理 {e} - 現象: 例外処理エラー, 影響: 安定性低下, 検出方法: テスト実行時例外, 推定原因: エラー処理未実装")