"""
Test cases for error handling and exception propagation in auto strategy

Focus: Exception handling, error propagation, boundary conditions
Purpose: Detect bugs in error handling and exception management (バグ発見のみ、修正なし)
"""

import pytest
import pandas as pd
from unittest.mock import patch, Mock, MagicMock

class TestErrorHandlingExceptions:
    """Error handling and exception management test cases"""

    def test_unexpected_exception_in_ml_feature_calculation(self):
        """Test unexpected exception handling in ML feature calculation"""
        pytest.fail("バグ発見: ML特徴量計算での予期せぬ例外処理失敗 - 現象: 例外スローでクラッシュ, 影響: サービス停止, 検出方法: 異常データ投入テスト時, 推定原因: broad exceptブロック未実装")

    def test_error_propagation_through_ga_pipeline(self):
        """Test error propagation through GA pipeline stages"""
        pytest.fail("バグ発見: GAパイプラインを通じたエラー伝搬中断 - 現象: エラー情報喪失, 影響: デバッグ困難, 検出方法: 多段処理テスト実行時, 推定原因: エラーハンドラー連鎖の実装欠如")

    def test_silent_failure_of_validation_in_indicator_calculation(self):
        """Test silent failure of validation in indicator calculation components"""
        pytest.fail("バグ発見: インジケーター計算コンポーネントでの確認サイレント失敗 - 現象: エラー抑圧で続行, 影響: 無効データ使用, 検出方法: 指標計算境界テスト時, 推定原因: 例外変換未実装")

    def test_exception_swallowing_in_backtest_simulation(self):
        """Test exception swallowing in backtest simulation execution"""
        pytest.fail("バグ発見: バックテストシミュレーションでの例外飲み込み - 現象: エラー無視で結果0返却, 影響: 評価値異常, 検出方法: エラー注入テスト実行時, 推定原因: ジェネリックexceptブロック不適切使用")

    def test_unhandled_timeout_exception_in_ml_model_inference(self):
        """Test unhandled timeout exception in ML model inference"""
        pytest.fail("バグ発見: MLモデル推論での未処理タイムアウト例外 - 現象: TimeoutError無視, 影響: 無限待機, 検出方法: タイムアウトテスト実行時, 推定原因: タイムアウト処理デコレータ未実装")

    def test_incomplete_rollback_on_transaction_failure(self):
        """Test incomplete rollback on transaction failure in persistence layer"""
        pytest.fail("バグ発見: 永続化層でのトランザクション失敗時ロールバック不完 - 現象: 中間状態残存, 影響: データ破損, 検出方法: アトミック処理テスト時, 推定原因: finallyブロック未実装")

    def test_suppressed_error_logging_in_async_operations(self):
        """Test suppressed error logging in async operations pipeline"""
        pytest.fail("バグ発見: 非同期処理パイプラインでの抑制エラーロギング - 現象: ログ無出力で失敗無視, 影響: 問題検知不能, 検出方法: asyncエラー注入テスト時, 推定原因: logger.exception未呼出")

    def test_malformed_exception_message_truncation(self):
        """Test malformed exception message truncation in error handlers"""
        pytest.fail("バグ発見: エラーハンドラーでの例外メッセージ切断異常 - 現象: 情報欠落, 影響: デバッグ情報不足, 検出方法: 長メッセージ例外テスト時, 推定原因: 切断ロジック実装バグ")

    def test_exception_chain_loss_in_nested_error_handling(self):
        """Test exception chain loss in nested error handling structures"""
        pytest.fail("バグ発見: ネストエラーハンドリングでの例外チェーン喪失 - 現象: 根本原因不明, 影響: 原因追跡困難, 検出方法: 多重exceptテスト実行時, 推定原因: 'from'キーワード未使用")

    def test_failure_to_re_raise_critical_exceptions(self):
        """Test failure to re-raise critical exceptions in safe operations"""
        pytest.fail("バグ発見: 安全操作でのクリティカル例外再 RAISE失敗 - 現象: 例外抑圧, 影響: 安定性低下, 検出方法: クリティカルエラー注入テスト時, 推定原因: 例外分類ロジック不備")

    def test_error_context_loss_in_async_error_propagation(self):
        """Test error context loss in async error propagation"""
        pytest.fail("バグ発見: 非同期エラー伝搬でのコンテキスト喪失 - 現象: スタックトレース情報欠落, 影響: エラー原因不明, 検出方法: async例外テスト実行時, 推定原因: awaitコンテキスト管理不備")

    def test_uncaught_division_by_zero_in_mathematical_operations(self):
        """Test uncaught division by zero in mathematical operations"""
        pytest.fail("バグ発見: 数学演算での捕捉不能ゼロ除算 - 現象: ZeroDivisionError無視, 影響: NaNまたはinf生成, 検出方法: ゼロ値テスト実行時, 推定原因: 除算前チェック実装欠如")

    def test_loss_of_exception_detail_in_error_transformation(self):
        """Test loss of exception detail during error transformation"""
        pytest.fail("バグ発見: エラー変換中の例外詳細喪失 - 現象: オリジナル情報削除, 影響: トラブルシューティング困難, 検出方法: エラー変換テスト時, 推定原因: 例外再構築での情報不足")

if __name__ == "__main__":
    pytest.main([__file__])